Workbook

Sheet README
B2: Duolingo 2023-2025 Sample Dataset for Dashboards
B3: Monthly data, Jan 2023 - Dec 2025 | Region x Platform x Language | Users, subscriptions, revenue, engagement, retention
B5: IMPORTANT
B6: This is SAMPLE / ILLUSTRATIVE data. Totals are modelled on the general public trends Duolingo has reported (rapid DAU growth, rising paid subscribers, subscription-led revenue), but region, platform, language, retention and engagement splits are synthetic. It is not official company data - do not cite it as such. For real figures use Duolingo's investor filings.
B7: SHEETS
B8: • Fact_Monthly - main fact table (648 rows). One row per Month x Region x Platform. 35 columns; yellow-header formulas are pre-built. Loaded as Excel table 'tblMonthly'.
B9: • Fact_Language - language-level table (396 rows). One row per Month x Language. Loaded as Excel table 'tblLanguage'.
B10: • Quarterly_Summary - quarterly and annual KPIs calculated with SUMIFS from Fact_Monthly (revenue, DAU, subs, YoY growth).
B11: • Events - three product/marketing milestones for chart annotations. Add your own rows.
B12: • Data_Dictionary - every column explained, with role (Dimension / Measure / Calculated), calculation, suggested dashboard use and priority (Key vs Supporting).
B13: HOW TO USE FOR AN INTERACTIVE DASHBOARD
B14: • Power BI / Tableau: import Fact_Monthly and Fact_Language; relate them on Date (and Language). Create a Date table if you want time intelligence.
... B23: • App_Store_Rating is intentionally blank for Web rows.

Sheet Data_Dictionary
A1: Sheet | B1: Column | C1: Data_Type | D1: Field_Role | E1: Description | F1: Calculation | G1: Suggested_Dashboard_Use | H1: Priority
A2: Fact_Monthly | B2: Date | C2: Date | D2: Dimension | E2: First day of the month. Grain of the table = Month x Region x Platform (648 rows). | F2: Input | G2: Time axis for line/area charts; date-range slicer or timeline filter. | H2: Key
A3: Fact_Monthly | B3: Year | C3: Integer | D3: Dimension | E3: Calendar year (2023-2025). | F3: Formula: YEAR(Date) | G3: Year slicer / buttons; YoY comparison series. | H3: Key
A4: Fact_Monthly | B4: Quarter | C4: Text | D4: Dimension | E4: Q1-Q4. | F4: Formula: "Q"&ROUNDUP(MONTH(Date)/3,0) | G4: Quarter slicer; seasonality analysis. | H4: Key
A5: Fact_Monthly | B5: Year_Quarter | C5: Text | D5: Dimension | E5: Label such as 2024-Q3. | F5: Year & '-' & Quarter | G5: X-axis for quarterly bar/line charts; join key to Quarterly_Summary. | H5: Key
A6: Fact_Monthly | B6: Month_Num | C6: Integer | D6: Dimension | E6: Month number 1-12. | F6: Formula: MONTH(Date) | G6: Sort key so Month_Name orders Jan-Dec. | H6: Supporting
A7: Fact_Monthly | B7: Month_Name | C7: Text | D7: Dimension | E7: Jan, Feb, ... Dec. | F7: Formula: TEXT(Date,"mmm") | G7: Seasonality heatmap; overlay 2023/2024/2025 lines by month. | H7: Supporting
A8: Fact_Monthly | B8: Region | C8: Text | D8: Dimension | E8: Six regions: North America, Europe, Asia Pacific, Latin America, Middle East & Africa, South Asia. | F8: Input | G8: Region slicer; filled map or bar chart; drill-down to platform. | H8: Key
A9: Fact_Monthly | B9: Platform | C9: Text | D9: Dimension | E9: iOS, Android or Web. | F9: Input | G9: Platform slicer; donut / stacked bar for platform mix. | H9: Key
A10: Fact_Monthly | B10: Monthly_Active_Users | C10: Integer | D10: Measure | E10: Users active at least once in the month (MAU). | F10: Input | G10: KPI card (sum of latest month); trend line. Sum across rows. | H10: Key
A11: Fact_Monthly | B11: Daily_Active_Users | C11: Integer | D11: Measure | E11: Average daily active users in the month (DAU). Duolingo's headline growth metric. | F11: Input | G11: KPI card; area chart by Region/Platform; YoY growth %. | H11: Key
A12: Fact_Monthly | B12: DAU_MAU_Ratio | C12: Percent | D12: Calculated | E12: Stickiness: share of monthly users who show up daily. | F12: Formula: DAU / MAU | G12: Gauge or line chart. For totals use SUM(DAU)/SUM(MAU), never average this column. | H12: Key
... A52: Events | B52: Event / Category | C52: Text | D52: Dimension | E52: Milestone description and type (Product, Marketing, Content). | F52: Input | G52: Tooltip / annotation labels on trend charts. | H52: Supporting

Sheet Fact_Monthly
A1: Date | B1: Year | C1: Quarter | D1: Year_Quarter | E1: Month_Num | F1: Month_Name | G1: Region | H1: Platform | I1: Monthly_Active_Users | J1: Daily_Active_Users | K1: DAU_MAU_Ratio | L1: New_Signups | M1: Super_Subscribers | N1: Family_Plan_Subscribers | O1: Max_Subscribers | P1: Total_Paid_Subscribers | Q1: Paid_Conversion_Rate | R1: Monthly_Paid_Churn_Pct | S1: Subscription_Revenue_USD | T1: Advertising_Revenue_USD | U1: In_App_Purchase_Revenue_USD | V1: DET_Revenue_USD | W1: Total_Revenue_USD | X1: ARPPU_USD | Y1: Revenue_per_DAU_USD | Z1: Marketing_Spend_USD | AA1: Cost_per_Signup_USD | AB1: Lessons_Completed | AC1: Avg_Session_Minutes | AD1: Avg_Streak_Days | AE1: Pct_DAU_With_7Day_Streak | AF1: D1_Retention | AG1: D7_Retention | AH1: D30_Retention | AI1: App_Store_Rating
A2: 44927 | B2: =YEAR(A2) -> 2023 | C2: ="Q"&ROUNDUP(MONTH(A2)/3,0) -> Q1 | D2: =B2&"-"&C2 -> 2023-Q1 | E2: =MONTH(A2) -> 1 | F2: =TEXT(A2,"mmm") -> Jan | G2: North America | H2: iOS | I2: 5696784 | J2: 1678662 | K2: =IF(I2=0,0,J2/I2) -> 0.29466836 | L2: 1008018 | M2: 1035717 | N2: 96132 | O2: 0 | P2: =M2+N2+O2 -> 1131849 | Q2: =IF(I2=0,0,P2/I2) -> 0.1986821 | R2: 0.0475 | S2: 7870321 | T2: 872173 | U2: 240366 | V2: 729020 | W2: =S2+T2+U2+V2 -> 9711880 | X2: =IF(P2=0,0,S2/P2) -> 6.9535079 | Y2: =IF(J2=0,0,W2/J2) -> 5.7854887 | Z2: 2139129 | AA2: =IF(L2=0,0,Z2/L2) -> 2.1221139 | AB2: 123278118 | AC2: 11.7 | AD2: 16 | AE2: 0.365 | AF2: 0.569 | AG2: 0.343 | AH2: 0.187 | AI2: 4.67
A3: 44927 | B3: =YEAR(A3) -> 2023 | C3: ="Q"&ROUNDUP(MONTH(A3)/3,0) -> Q1 | D3: =B3&"-"&C3 -> 2023-Q1 | E3: =MONTH(A3) -> 1 | F3: =TEXT(A3,"mmm") -> Jan | G3: North America | H3: Android | I3: 6891491 | J3: 1847127 | K3: =IF(I3=0,0,J3/I3) -> 0.2680301 | L3: 1101786 | M3: 597101 | N3: 53841 | O3: 0 | P3: =M3+N3+O3 -> 650942 | Q3: =IF(I3=0,0,P3/I3) -> 0.094455902 | R3: 0.0449 | S3: 4902294 | T3: 431173 | U3: 151270 | V3: 378708 | W3: =S3+T3+U3+V3 -> 5863445 | X3: =IF(P3=0,0,S3/P3) -> 7.5310765 | Y3: =IF(J3=0,0,W3/J3) -> 3.1743594 | Z3: 976750 | AA3: =IF(L3=0,0,Z3/L3) -> 0.88651517 | AB3: 131752466 | AC3: 11.1 | AD3: 17 | AE3: 0.34 | AF3: 0.551 | AG3: 0.343 | AH3: 0.19 | AI3: 4.61
A4: 44927 | B4: =YEAR(A4) -> 2023 | C4: ="Q"&ROUNDUP(MONTH(A4)/3,0) -> Q1 | D4: =B4&"-"&C4 -> 2023-Q1 | E4: =MONTH(A4) -> 1 | F4: =TEXT(A4,"mmm") -> Jan | G4: North America | H4: Web | I4: 2445452 | J4: 599773 | K4: =IF(I4=0,0,J4/I4) -> 0.24526059 | L4: 341479 | M4: 169195 | N4: 15357 | O4: 0 | P4: =M4+N4+O4 -> 184552 | Q4: =IF(I4=0,0,P4/I4) -> 0.075467439 | R4: 0.0517 | S4: 1304157 | T4: 133171 | U4: 43831 | V4: 112666 | W4: =S4+T4+U4+V4 -> 1593825 | X4: =IF(P4=0,0,S4/P4) -> 7.06661 | Y4: =IF(J4=0,0,W4/J4) -> 2.6573804 | Z4: 311412 | AA4: =IF(L4=0,0,Z4/L4) -> 0.91195066 | AB4: 40888516 | AC4: 9.9 | AD4: 17.6 | AE4: 0.353 | AF4: 0.568 | AG4: 0.318 | AH4: 0.189
A5: 44927 | B5: =YEAR(A5) -> 2023 | C5: ="Q"&ROUNDUP(MONTH(A5)/3,0) -> Q1 | D5: =B5&"-"&C5 -> 2023-Q1 | E5: =MONTH(A5) -> 1 | F5: =TEXT(A5,"mmm") -> Jan | G5: Europe | H5: iOS | I5: 6407171 | J5: 1943139 | K5: =IF(I5=0,0,J5/I5) -> 0.30327566 | L5: 1337396 | M5: 647014 | N5: 55084 | O5: 0 | P5: =M5+N5+O5 -> 702098 | Q5: =IF(I5=0,0,P5/I5) -> 0.10958003 | R5: 0.0423 | S5: 4983929 | T5: 545121 | U5: 167735 | V5: 439859 | W5: =S5+T5+U5+V5 -> 6136644 | X5: =IF(P5=0,0,S5/P5) -> 7.098623 | Y5: =IF(J5=0,0,W5/J5) -> 3.1581086 | Z5: 1321431 | AA5: =IF(L5=0,0,Z5/L5) -> 0.98806262 | AB5: 144135851 | AC5: 11.5 | AD5: 17.2 | AE5: 0.372 | AF5: 0.55 | AG5: 0.322 | AH5: 0.187 | AI5: 4.65
A6: 44927 | B6: =YEAR(A6) -> 2023 | C6: ="Q"&ROUNDUP(MONTH(A6)/3,0) -> Q1 | D6: =B6&"-"&C6 -> 2023-Q1 | E6: =MONTH(A6) -> 1 | F6: =TEXT(A6,"mmm") -> Jan | G6: Europe | H6: Android | I6: 8542654 | J6: 2403457 | K6: =IF(I6=0,0,J6/I6) -> 0.28134781 | L6: 1300355 | M6: 358538 | N6: 31301 | O6: 0 | P6: =M6+N6+O6 -> 389839 | Q6: =IF(I6=0,0,P6/I6) -> 0.045634413 | R6: 0.0435 | S6: 2533195 | T6: 239795 | U6: 68295 | V6: 216368 | W6: =S6+T6+U6+V6 -> 3057653 | X6: =IF(P6=0,0,S6/P6) -> 6.4980543 | Y6: =IF(J6=0,0,W6/J6) -> 1.2721896 | Z6: 614422 | AA6: =IF(L6=0,0,Z6/L6) -> 0.47250328 | AB6: 179274870 | AC6: 11.2 | AD6: 15.9 | AE6: 0.362 | AF6: 0.553 | AG6: 0.318 | AH6: 0.197 | AI6: 4.62
A7: 44927 | B7: =YEAR(A7) -> 2023 | C7: ="Q"&ROUNDUP(MONTH(A7)/3,0) -> Q1 | D7: =B7&"-"&C7 -> 2023-Q1 | E7: =MONTH(A7) -> 1 | F7: =TEXT(A7,"mmm") -> Jan | G7: Europe | H7: Web | I7: 2763143 | J7: 679396 | K7: =IF(I7=0,0,J7/I7) -> 0.24587797 | L7: 404594 | M7: 99286 | N7: 8812 | O7: 0 | P7: =M7+N7+O7 -> 108098 | Q7: =IF(I7=0,0,P7/I7) -> 0.039121392 | R7: 0.0479 | S7: 764751 | T7: 81986 | U7: 24158 | V7: 63657 | W7: =S7+T7+U7+V7 -> 934552 | X7: =IF(P7=0,0,S7/P7) -> 7.0746082 | Y7: =IF(J7=0,0,W7/J7) -> 1.375563 | Z7: 188119 | AA7: =IF(L7=0,0,Z7/L7) -> 0.46495746 | AB7: 46385070 | AC7: 9.8 | AD7: 16.4 | AE7: 0.365 | AF7: 0.563 | AG7: 0.332 | AH7: 0.192
A8: 44927 | B8: =YEAR(A8) -> 2023 | C8: ="Q"&ROUNDUP(MONTH(A8)/3,0) -> Q1 | D8: =B8&"-"&C8 -> 2023-Q1 | E8: =MONTH(A8) -> 1 | F8: =TEXT(A8,"mmm") -> Jan | G8: Asia Pacific | H8: iOS | I8: 4593757 | J8: 1310763 | K8: =IF(I8=0,0,J8/I8) -> 0.28533573 | L8: 795895 | M8: 291757 | N8: 23967 | O8: 0 | P8: =M8+N8+O8 -> 315724 | Q8: =IF(I8=0,0,P8/I8) -> 0.068728929 | R8: 0.0477 | S8: 1894518 | T8: 181342 | U8: 57810 | V8: 153201 | W8: =S8+T8+U8+V8 -> 2286871 | X8: =IF(P8=0,0,S8/P8) -> 6.0005511 | Y8: =IF(J8=0,0,W8/J8) -> 1.7446869 | Z8: 385572 | AA8: =IF(L8=0,0,Z8/L8) -> 0.48445084 | AB8: 93713913 | AC8: 11.6 | AD8: 16.8 | AE8: 0.352 | AF8: 0.559 | AG8: 0.339 | AH8: 0.184 | AI8: 4.63
A9: 44927 | B9: =YEAR(A9) -> 2023 | C9: ="Q"&ROUNDUP(MONTH(A9)/3,0) -> Q1 | D9: =B9&"-"&C9 -> 2023-Q1 | E9: =MONTH(A9) -> 1 | F9: =TEXT(A9,"mmm") -> Jan | G9: Asia Pacific | H9: Android | I9: 5867156 | J9: 1502855 | K9: =IF(I9=0,0,J9/I9) -> 0.2561471 | L9: 926437 | M9: 144307 | N9: 12978 | O9: 0 | P9: =M9+N9+O9 -> 157285 | Q9: =IF(I9=0,0,P9/I9) -> 0.026807707 | R9: 0.0506 | S9: 1174494 | T9: 119201 | U9: 36342 | V9: 99715 | W9: =S9+T9+U9+V9 -> 1429752 | X9: =IF(P9=0,0,S9/P9) -> 7.4672982 | Y9: =IF(J9=0,0,W9/J9) -> 0.95135725 | Z9: 272213 | AA9: =IF(L9=0,0,Z9/L9) -> 0.29382786 | AB9: 110064852 | AC9: 11.4 | AD9: 16.2 | AE9: 0.353 | AF9: 0.563 | AG9: 0.351 | AH9: 0.194 | AI9: 4.57
A10: 44927 | B10: =YEAR(A10) -> 2023 | C10: ="Q"&ROUNDUP(MONTH(A10)/3,0) -> Q1 | D10: =B10&"-"&C10 -> 2023-Q1 | E10: =MONTH(A10) -> 1 | F10: =TEXT(A10,"mmm") -> Jan | G10: Asia Pacific | H10: Web | I10: 1861870 | J10: 433880 | K10: =IF(I10=0,0,J10/I10) -> 0.23303453 | L10: 241166 | M10: 41088 | N10: 3949 | O10: 0 | P10: =M10+N10+O10 -> 45037 | Q10: =IF(I10=0,0,P10/I10) -> 0.024189122 | R10: 0.049 | S10: 287296 | T10: 32637 | U10: 8883 | V10: 25077 | W10: =S10+T10+U10+V10 -> 353893 | X10: =IF(P10=0,0,S10/P10) -> 6.3791105 | Y10: =IF(J10=0,0,W10/J10) -> 0.81564718 | Z10: 68888 | AA10: =IF(L10=0,0,Z10/L10) -> 0.28564557 | AB10: 32233734 | AC10: 10.2 | AD10: 17.2 | AE10: 0.368 | AF10: 0.586 | AG10: 0.323 | AH10: 0.187
A11: 44927 | B11: =YEAR(A11) -> 2023 | C11: ="Q"&ROUNDUP(MONTH(A11)/3,0) -> Q1 | D11: =B11&"-"&C11 -> 2023-Q1 | E11: =MONTH(A11) -> 1 | F11: =TEXT(A11,"mmm") -> Jan | G11: Latin America | H11: iOS | I11: 4188579 | J11: 1242919 | K11: =IF(I11=0,0,J11/I11) -> 0.29674002 | L11: 699147 | M11: 142493 | N11: 12078 | O11: 0 | P11: =M11+N11+O11 -> 154571 | Q11: =IF(I11=0,0,P11/I11) -> 0.036902969 | R11: 0.05 | S11: 1103756 | T11: 101080 | U11: 34105 | V11: 90114 | W11: =S11+T11+U11+V11 -> 1329055 | X11: =IF(P11=0,0,S11/P11) -> 7.1407703 | Y11: =IF(J11=0,0,W11/J11) -> 1.0693014 | Z11: 218901 | AA11: =IF(L11=0,0,Z11/L11) -> 0.31309725 | AB11: 86123012 | AC11: 11.4 | AD11: 16.2 | AE11: 0.356 | AF11: 0.569 | AG11: 0.333 | AH11: 0.188 | AI11: 4.64
A12: 44927 | B12: =YEAR(A12) -> 2023 | C12: ="Q"&ROUNDUP(MONTH(A12)/3,0) -> Q1 | D12: =B12&"-"&C12 -> 2023-Q1 | E12: =MONTH(A12) -> 1 | F12: =TEXT(A12,"mmm") -> Jan | G12: Latin America | H12: Android | I12: 5450075 | J12: 1466214 | K12: =IF(I12=0,0,J12/I12) -> 0.26902639 | L12: 838396 | M12: 74682 | N12: 6203 | O12: 0 | P12: =M12+N12+O12 -> 80885 | Q12: =IF(I12=0,0,P12/I12) -> 0.01484108 | R12: 0.0474 | S12: 571410 | T12: 58187 | U12: 17803 | V12: 44890 | W12: =S12+T12+U12+V12 -> 692290 | X12: =IF(P12=0,0,S12/P12) -> 7.0644743 | Y12: =IF(J12=0,0,W12/J12) -> 0.47216164 | Z12: 123847 | AA12: =IF(L12=0,0,Z12/L12) -> 0.14771898 | AB12: 112751883 | AC12: 11 | AD12: 17.2 | AE12: 0.359 | AF12: 0.56 | AG12: 0.328 | AH12: 0.186 | AI12: 4.6
A13: 44927 | B13: =YEAR(A13) -> 2023 | C13: ="Q"&ROUNDUP(MONTH(A13)/3,0) -> Q1 | D13: =B13&"-"&C13 -> 2023-Q1 | E13: =MONTH(A13) -> 1 | F13: =TEXT(A13,"mmm") -> Jan | G13: Latin America | H13: Web | I13: 1443854 | J13: 362386 | K13: =IF(I13=0,0,J13/I13) -> 0.25098521 | L13: 233058 | M13: 21828 | N13: 2168 | O13: 0 | P13: =M13+N13+O13 -> 23996 | Q13: =IF(I13=0,0,P13/I13) -> 0.016619409 | R13: 0.046 | S13: 173347 | T13: 17836 | U13: 5773 | V13: 16207 | W13: =S13+T13+U13+V13 -> 213163 | X13: =IF(P13=0,0,S13/P13) -> 7.2239957 | Y13: =IF(J13=0,0,W13/J13) -> 0.58822085 | Z13: 41309 | AA13: =IF(L13=0,0,Z13/L13) -> 0.17724772 | AB13: 25213966 | AC13: 10.1 | AD13: 16.1 | AE13: 0.359 | AF13: 0.553 | AG13: 0.335 | AH13: 0.191
A14: 44927 | B14: =YEAR(A14) -> 2023 | C14: ="Q"&ROUNDUP(MONTH(A14)/3,0) -> Q1 | D14: =B14&"-"&C14 -> 2023-Q1 | E14: =MONTH(A14) -> 1 | F14: =TEXT(A14,"mmm") -> Jan | G14: Middle East & Africa | H14: iOS | I14: 2503691 | J14: 712495 | K14: =IF(I14=0,0,J14/I14) -> 0.28457785 | L14: 428742 | M14: 44545 | N14: 4073 | O14: 0 | P14: =M14+N14+O14 -> 48618 | Q14: =IF(I14=0,0,P14/I14) -> 0.01941853 | R14: 0.0448 | S14: 353298 | T14: 32441 | U14: 11035 | V14: 26529 | W14: =S14+T14+U14+V14 -> 423303 | X14: =IF(P14=0,0,S14/P14) -> 7.2668148 | Y14: =IF(J14=0,0,W14/J14) -> 0.59411364 | Z14: 76411 | AA14: =IF(L14=0,0,Z14/L14) -> 0.1782214 | AB14: 51163533 | AC14: 11.6 | AD14: 16.9 | AE14: 0.37 | AF14: 0.567 | AG14: 0.331 | AH14: 0.193 | AI14: 4.65
A15: 44927 | B15: =YEAR(A15) -> 2023 | C15: ="Q"&ROUNDUP(MONTH(A15)/3,0) -> Q1 | D15: =B15&"-"&C15 -> 2023-Q1 | E15: =MONTH(A15) -> 1 | F15: =TEXT(A15,"mmm") -> Jan | G15: Middle East & Africa | H15: Android | I15: 3220442 | J15: 825341 | K15: =IF(I15=0,0,J15/I15) -> 0.2562819 | L15: 526205 | M15: 25125 | N15: 2360 | O15: 0 | P15: =M15+N15+O15 -> 27485 | Q15: =IF(I15=0,0,P15/I15) -> 0.0085345428 | R15: 0.0485 | S15: 202936 | T15: 20749 | U15: 6392 | V15: 16945 | W15: =S15+T15+U15+V15 -> 247022 | X15: =IF(P15=0,0,S15/P15) -> 7.3835183 | Y15: =IF(J15=0,0,W15/J15) -> 0.2992969 | Z15: 42139 | AA15: =IF(L15=0,0,Z15/L15) -> 0.080080957 | AB15: 60345645 | AC15: 11.3 | AD15: 16.8 | AE15: 0.34 | AF15: 0.552 | AG15: 0.339 | AH15: 0.195 | AI15: 4.61
A16: 44927 | B16: =YEAR(A16) -> 2023 | C16: ="Q"&ROUNDUP(MONTH(A16)/3,0) -> Q1 | D16: =B16&"-"&C16 -> 2023-Q1 | E16: =MONTH(A16) -> 1 | F16: =TEXT(A16,"mmm") -> Jan | G16: Middle East & Africa | H16: Web | I16: 1166086 | J16: 273490 | K16: =IF(I16=0,0,J16/I16) -> 0.23453673 | L16: 136608 | M16: 6999 | N16: 615 | O16: 0 | P16: =M16+N16+O16 -> 7614 | Q16: =IF(I16=0,0,P16/I16) -> 0.0065295356 | R16: 0.0492 | S16: 54039 | T16: 6042 | U16: 1588 | V16: 4977 | W16: =S16+T16+U16+V16 -> 66646 | X16: =IF(P16=0,0,S16/P16) -> 7.0973207 | Y16: =IF(J16=0,0,W16/J16) -> 0.24368715 | Z16: 13237 | AA16: =IF(L16=0,0,Z16/L16) -> 0.096897693 | AB16: 19063796 | AC16: 10.1 | AD16: 17.3 | AE16: 0.359 | AF16: 0.555 | AG16: 0.321 | AH16: 0.184
A17: 44927 | B17: =YEAR(A17) -> 2023 | C17: ="Q"&ROUNDUP(MONTH(A17)/3,0) -> Q1 | D17: =B17&"-"&C17 -> 2023-Q1 | E17: =MONTH(A17) -> 1 | F17: =TEXT(A17,"mmm") -> Jan | G17: South Asia | H17: iOS | I17: 3744028 | J17: 1015248 | K17: =IF(I17=0,0,J17/I17) -> 0.27116464 | L17: 636438 | M17: 91176 | N17: 8413 | O17: 0 | P17: =M17+N17+O17 -> 99589 | Q17: =IF(I17=0,0,P17/I17) -> 0.026599427 | R17: 0.048 | S17: 739202 | T17: 77366 | U17: 20772 | V17: 64765 | W17: =S17+T17+U17+V17 -> 902105 | X17: =IF(P17=0,0,S17/P17) -> 7.4225266 | Y17: =IF(J17=0,0,W17/J17) -> 0.88855629 | Z17: 176240 | AA17: =IF(L17=0,0,Z17/L17) -> 0.27691621 | AB17: 73388090 | AC17: 11.6 | AD17: 17.5 | AE17: 0.366 | AF17: 0.568 | AG17: 0.336 | AH17: 0.194 | AI17: 4.64
A18: 44927 | B18: =YEAR(A18) -> 2023 | C18: ="Q"&ROUNDUP(MONTH(A18)/3,0) -> Q1 | D18: =B18&"-"&C18 -> 2023-Q1 | E18: =MONTH(A18) -> 1 | F18: =TEXT(A18,"mmm") -> Jan | G18: South Asia | H18: Android | I18: 5162153 | J18: 1313250 | K18: =IF(I18=0,0,J18/I18) -> 0.25439967 | L18: 735236 | M18: 50996 | N18: 4513 | O18: 0 | P18: =M18+N18+O18 -> 55509 | Q18: =IF(I18=0,0,P18/I18) -> 0.010753071 | R18: 0.0466 | S18: 397120 | T18: 37616 | U18: 11341 | V18: 31013 | W18: =S18+T18+U18+V18 -> 477090 | X18: =IF(P18=0,0,S18/P18) -> 7.1541552 | Y18: =IF(J18=0,0,W18/J18) -> 0.36328955 | Z18: 85323 | AA18: =IF(L18=0,0,Z18/L18) -> 0.11604845 | AB18: 96746940 | AC18: 11.2 | AD18: 16.5 | AE18: 0.36 | AF18: 0.56 | AG18: 0.327 | AH18: 0.185 | AI18: 4.61
A19: 44927 | B19: =YEAR(A19) -> 2023 | C19: ="Q"&ROUNDUP(MONTH(A19)/3,0) -> Q1 | D19: =B19&"-"&C19 -> 2023-Q1 | E19: =MONTH(A19) -> 1 | F19: =TEXT(A19,"mmm") -> Jan | G19: South Asia | H19: Web | I19: 1367456 | J19: 313605 | K19: =IF(I19=0,0,J19/I19) -> 0.22933462 | L19: 184042 | M19: 14966 | N19: 1343 | O19: 0 | P19: =M19+N19+O19 -> 16309 | Q19: =IF(I19=0,0,P19/I19) -> 0.011926526 | R19: 0.0492 | S19: 100596 | T19: 11466 | U19: 3247 | V19: 9145 | W19: =S19+T19+U19+V19 -> 124454 | X19: =IF(P19=0,0,S19/P19) -> 6.168128 | Y19: =IF(J19=0,0,W19/J19) -> 0.39684954 | Z19: 22468 | AA19: =IF(L19=0,0,Z19/L19) -> 0.12208083 | AB19: 23718812 | AC19: 10.1 | AD19: 17.2 | AE19: 0.341 | AF19: 0.555 | AG19: 0.331 | AH19: 0.185
A20: 44958 | B20: =YEAR(A20) -> 2023 | C20: ="Q"&ROUNDUP(MONTH(A20)/3,0) -> Q1 | D20: =B20&"-"&C20 -> 2023-Q1 | E20: =MONTH(A20) -> 2 | F20: =TEXT(A20,"mmm") -> Feb | G20: North America | H20: iOS | I20: 5643187 | J20: 1687961 | K20: =IF(I20=0,0,J20/I20) -> 0.29911484 | L20: 987334 | M20: 1120316 | N20: 102335 | O20: 0 | P20: =M20+N20+O20 -> 1222651 | Q20: =IF(I20=0,0,P20/I20) -> 0.21665966 | R20: 0.0464 | S20: 8198883 | T20: 853347 | U20: 285489 | V20: 678466 | W20: =S20+T20+U20+V20 -> 10016185 | X20: =IF(P20=0,0,S20/P20) -> 6.7058245 | Y20: =IF(J20=0,0,W20/J20) -> 5.933896 | Z20: 1882198 | AA20: =IF(L20=0,0,Z20/L20) -> 1.9063437 | AB20: 124647205 | AC20: 11.7 | AD20: 16.7 | AE20: 0.351 | AF20: 0.571 | AG20: 0.328 | AH20: 0.187 | AI20: 4.64
A21: 44958 | B21: =YEAR(A21) -> 2023 | C21: ="Q"&ROUNDUP(MONTH(A21)/3,0) -> Q1 | D21: =B21&"-"&C21 -> 2023-Q1 | E21: =MONTH(A21) -> 2 | F21: =TEXT(A21,"mmm") -> Feb | G21: North America | H21: Android | I21: 7900264 | J21: 2122583 | K21: =IF(I21=0,0,J21/I21) -> 0.26867241 | L21: 1069500 | M21: 597051 | N21: 54574 | O21: 0 | P21: =M21+N21+O21 -> 651625 | Q21: =IF(I21=0,0,P21/I21) -> 0.082481421 | R21: 0.0488 | S21: 4987758 | T21: 493582 | U21: 155271 | V21: 389604 | W21: =S21+T21+U21+V21 -> 6026215 | X21: =IF(P21=0,0,S21/P21) -> 7.654338 | Y21: =IF(J21=0,0,W21/J21) -> 2.8390951 | Z21: 1100984 | AA21: =IF(L21=0,0,Z21/L21) -> 1.0294381 | AB21: 155866606 | AC21: 11.1 | AD21: 17.1 | AE21: 0.361 | AF21: 0.566 | AG21: 0.332 | AH21: 0.187 | AI21: 4.59
A22: 44958 | B22: =YEAR(A22) -> 2023 | C22: ="Q"&ROUNDUP(MONTH(A22)/3,0) -> Q1 | D22: =B22&"-"&C22 -> 2023-Q1 | E22: =MONTH(A22) -> 2 | F22: =TEXT(A22,"mmm") -> Feb | G22: North America | H22: Web | I22: 2288214 | J22: 550824 | K22: =IF(I22=0,0,J22/I22) -> 0.24072224 | L22: 283389 | M22: 185671 | N22: 16338 | O22: 0 | P22: =M22+N22+O22 -> 202009 | Q22: =IF(I22=0,0,P22/I22) -> 0.08828239 | R22: 0.049 | S22: 1411769 | T22: 141854 | U22: 45146 | V22: 117524 | W22: =S22+T22+U22+V22 -> 1716293 | X22: =IF(P22=0,0,S22/P22) -> 6.9886441 | Y22: =IF(J22=0,0,W22/J22) -> 3.1158646 | Z22: 333963 | AA22: =IF(L22=0,0,Z22/L22) -> 1.1784614 | AB22: 38080915 | AC22: 10.1 | AD22: 17.5 | AE22: 0.357 | AF22: 0.569 | AG22: 0.321 | AH22: 0.193
A23: 44958 | B23: =YEAR(A23) -> 2023 | C23: ="Q"&ROUNDUP(MONTH(A23)/3,0) -> Q1 | D23: =B23&"-"&C23 -> 2023-Q1 | E23: =MONTH(A23) -> 2 | F23: =TEXT(A23,"mmm") -> Feb | G23: Europe | H23: iOS | I23: 7031091 | J23: 2125033 | K23: =IF(I23=0,0,J23/I23) -> 0.30223375 | L23: 1097592 | M23: 668241 | N23: 59879 | O23: 0 | P23: =M23+N23+O23 -> 728120 | Q23: =IF(I23=0,0,P23/I23) -> 0.10355719 | R23: 0.045 | S23: 6001377 | T23: 609355 | U23: 185825 | V23: 541976 | W23: =S23+T23+U23+V23 -> 7338533 | X23: =IF(P23=0,0,S23/P23) -> 8.2422911 | Y23: =IF(J23=0,0,W23/J23) -> 3.4533737 | Z23: 1566720 | AA23: =IF(L23=0,0,Z23/L23) -> 1.4274157 | AB23: 150021214 | AC23: 11.6 | AD23: 16.7 | AE23: 0.354 | AF23: 0.566 | AG23: 0.331 | AH23: 0.195 | AI23: 4.67
A24: 44958 | B24: =YEAR(A24) -> 2023 | C24: ="Q"&ROUNDUP(MONTH(A24)/3,0) -> Q1 | D24: =B24&"-"&C24 -> 2023-Q1 | E24: =MONTH(A24) -> 2 | F24: =TEXT(A24,"mmm") -> Feb | G24: Europe | H24: Android | I24: 8041939 | J24: 2250204 | K24: =IF(I24=0,0,J24/I24) -> 0.27980864 | L24: 1052825 | M24: 383485 | N24: 31946 | O24: 0 | P24: =M24+N24+O24 -> 415431 | Q24: =IF(I24=0,0,P24/I24) -> 0.051658064 | R24: 0.0477 | S24: 2872883 | T24: 286445 | U24: 98706 | V24: 247708 | W24: =S24+T24+U24+V24 -> 3505742 | X24: =IF(P24=0,0,S24/P24) -> 6.9154276 | Y24: =IF(J24=0,0,W24/J24) -> 1.5579663 | Z24: 719492 | AA24: =IF(L24=0,0,Z24/L24) -> 0.68339183 | AB24: 162581945 | AC24: 11.1 | AD24: 18 | AE24: 0.367 | AF24: 0.566 | AG24: 0.333 | AH24: 0.193 | AI24: 4.57
A25: 44958 | B25: =YEAR(A25) -> 2023 | C25: ="Q"&ROUNDUP(MONTH(A25)/3,0) -> Q1 | D25: =B25&"-"&C25 -> 2023-Q1 | E25: =MONTH(A25) -> 2 | F25: =TEXT(A25,"mmm") -> Feb | G25: Europe | H25: Web | I25: 2525191 | J25: 662827 | K25: =IF(I25=0,0,J25/I25) -> 0.26248589 | L25: 313890 | M25: 104880 | N25: 9711 | O25: 0 | P25: =M25+N25+O25 -> 114591 | Q25: =IF(I25=0,0,P25/I25) -> 0.045379142 | R25: 0.0509 | S25: 911375 | T25: 89389 | U25: 28375 | V25: 70327 | W25: =S25+T25+U25+V25 -> 1099466 | X25: =IF(P25=0,0,S25/P25) -> 7.953286 | Y25: =IF(J25=0,0,W25/J25) -> 1.6587526 | Z25: 208261 | AA25: =IF(L25=0,0,Z25/L25) -> 0.66348402 | AB25: 48581956 | AC25: 10.3 | AD25: 17.3 | AE25: 0.361 | AF25: 0.559 | AG25: 0.332 | AH25: 0.189
A26: 44958 | B26: =YEAR(A26) -> 2023 | C26: ="Q"&ROUNDUP(MONTH(A26)/3,0) -> Q1 | D26: =B26&"-"&C26 -> 2023-Q1 | E26: =MONTH(A26) -> 2 | F26: =TEXT(A26,"mmm") -> Feb | G26: Asia Pacific | H26: iOS | I26: 4372466 | J26: 1252377 | K26: =IF(I26=0,0,J26/I26) -> 0.2864235 | L26: 653280 | M26: 282799 | N26: 25195 | O26: 0 | P26: =M26+N26+O26 -> 307994 | Q26: =IF(I26=0,0,P26/I26) -> 0.070439427 | R26: 0.0501 | S26: 2351562 | T26: 242304 | U26: 80994 | V26: 187556 | W26: =S26+T26+U26+V26 -> 2862416 | X26: =IF(P26=0,0,S26/P26) -> 7.6350903 | Y26: =IF(J26=0,0,W26/J26) -> 2.2855865 | Z26: 586012 | AA26: =IF(L26=0,0,Z26/L26) -> 0.89703037 | AB26: 87311390 | AC26: 12.1 | AD26: 17.1 | AE26: 0.363 | AF26: 0.564 | AG26: 0.335 | AH26: 0.185 | AI26: 4.65
A27: 44958 | B27: =YEAR(A27) -> 2023 | C27: ="Q"&ROUNDUP(MONTH(A27)/3,0) -> Q1 | D27: =B27&"-"&C27 -> 2023-Q1 | E27: =MONTH(A27) -> 2 | F27: =TEXT(A27,"mmm") -> Feb | G27: Asia Pacific | H27: Android | I27: 5873191 | J27: 1544722 | K27: =IF(I27=0,0,J27/I27) -> 0.26301239 | L27: 670668 | M27: 155618 | N27: 15227 | O27: 0 | P27: =M27+N27+O27 -> 170845 | Q27: =IF(I27=0,0,P27/I27) -> 0.029088957 | R27: 0.0456 | S27: 1376967 | T27: 136511 | U27: 46358 | V27: 127491 | W27: =S27+T27+U27+V27 -> 1687327 | X27: =IF(P27=0,0,S27/P27) -> 8.0597442 | Y27: =IF(J27=0,0,W27/J27) -> 1.0923176 | Z27: 335060 | AA27: =IF(L27=0,0,Z27/L27) -> 0.49959145 | AB27: 110422232 | AC27: 11.6 | AD27: 18.1 | AE27: 0.36 | AF27: 0.562 | AG27: 0.338 | AH27: 0.195 | AI27: 4.6
A28: 44958 | B28: =YEAR(A28) -> 2023 | C28: ="Q"&ROUNDUP(MONTH(A28)/3,0) -> Q1 | D28: =B28&"-"&C28 -> 2023-Q1 | E28: =MONTH(A28) -> 2 | F28: =TEXT(A28,"mmm") -> Feb | G28: Asia Pacific | H28: Web | I28: 1828051 | J28: 443311 | K28: =IF(I28=0,0,J28/I28) -> 0.24250472 | L28: 224056 | M28: 44279 | N28: 4059 | O28: 0 | P28: =M28+N28+O28 -> 48338 | Q28: =IF(I28=0,0,P28/I28) -> 0.026442369 | R28: 0.0504 | S28: 352082 | T28: 32224 | U28: 12543 | V28: 30111 | W28: =S28+T28+U28+V28 -> 426960 | X28: =IF(P28=0,0,S28/P28) -> 7.2837519 | Y28: =IF(J28=0,0,W28/J28) -> 0.96311619 | Z28: 79348 | AA28: =IF(L28=0,0,Z28/L28) -> 0.35414361 | AB28: 32088506 | AC28: 10.3 | AD28: 16.9 | AE28: 0.363 | AF28: 0.569 | AG28: 0.338 | AH28: 0.188
A29: 44958 | B29: =YEAR(A29) -> 2023 | C29: ="Q"&ROUNDUP(MONTH(A29)/3,0) -> Q1 | D29: =B29&"-"&C29 -> 2023-Q1 | E29: =MONTH(A29) -> 2 | F29: =TEXT(A29,"mmm") -> Feb | G29: Latin America | H29: iOS | I29: 3896435 | J29: 1188326 | K29: =IF(I29=0,0,J29/I29) -> 0.30497776 | L29: 643399 | M29: 139742 | N29: 12243 | O29: 0 | P29: =M29+N29+O29 -> 151985 | Q29: =IF(I29=0,0,P29/I29) -> 0.039006168 | R29: 0.0511 | S29: 1161710 | T29: 133074 | U29: 39193 | V29: 95685 | W29: =S29+T29+U29+V29 -> 1429662 | X29: =IF(P29=0,0,S29/P29) -> 7.6435832 | Y29: =IF(J29=0,0,W29/J29) -> 1.2030891 | Z29: 265150 | AA29: =IF(L29=0,0,Z29/L29) -> 0.41210819 | AB29: 84110372 | AC29: 11.7 | AD29: 17.5 | AE29: 0.364 | AF29: 0.563 | AG29: 0.334 | AH29: 0.185 | AI29: 4.64
A30: 44958 | B30: =YEAR(A30) -> 2023 | C30: ="Q"&ROUNDUP(MONTH(A30)/3,0) -> Q1 | D30: =B30&"-"&C30 -> 2023-Q1 | E30: =MONTH(A30) -> 2 | F30: =TEXT(A30,"mmm") -> Feb | G30: Latin America | H30: Android | I30: 5563411 | J30: 1538388 | K30: =IF(I30=0,0,J30/I30) -> 0.27651885 | L30: 706505 | M30: 83946 | N30: 6920 | O30: 0 | P30: =M30+N30+O30 -> 90866 | Q30: =IF(I30=0,0,P30/I30) -> 0.016332786 | R30: 0.0487 | S30: 654905 | T30: 70133 | U30: 20259 | V30: 55697 | W30: =S30+T30+U30+V30 -> 800994 | X30: =IF(P30=0,0,S30/P30) -> 7.2073713 | Y30: =IF(J30=0,0,W30/J30) -> 0.52067099 | Z30: 162113 | AA30: =IF(L30=0,0,Z30/L30) -> 0.22945768 | AB30: 111158938 | AC30: 11.5 | AD30: 17.8 | AE30: 0.37 | AF30: 0.566 | AG30: 0.342 | AH30: 0.189 | AI30: 4.57
A31: 44958 | B31: =YEAR(A31) -> 2023 | C31: ="Q"&ROUNDUP(MONTH(A31)/3,0) -> Q1 | D31: =B31&"-"&C31 -> 2023-Q1 | E31: =MONTH(A31) -> 2 | F31: =TEXT(A31,"mmm") -> Feb | G31: Latin America | H31: Web | I31: 1663339 | J31: 426456 | K31: =IF(I31=0,0,J31/I31) -> 0.2563855 | L31: 196963 | M31: 21369 | N31: 1989 | O31: 0 | P31: =M31+N31+O31 -> 23358 | Q31: =IF(I31=0,0,P31/I31) -> 0.014042838 | R31: 0.0491 | S31: 174941 | T31: 17126 | U31: 5571 | V31: 15323 | W31: =S31+T31+U31+V31 -> 212961 | X31: =IF(P31=0,0,S31/P31) -> 7.4895539 | Y31: =IF(J31=0,0,W31/J31) -> 0.49937391 | Z31: 41899 | AA31: =IF(L31=0,0,Z31/L31) -> 0.21272523 | AB31: 30641024 | AC31: 10.1 | AD31: 17.8 | AE31: 0.361 | AF31: 0.563 | AG31: 0.336 | AH31: 0.187
A32: 44958 | B32: =YEAR(A32) -> 2023 | C32: ="Q"&ROUNDUP(MONTH(A32)/3,0) -> Q1 | D32: =B32&"-"&C32 -> 2023-Q1 | E32: =MONTH(A32) -> 2 | F32: =TEXT(A32,"mmm") -> Feb | G32: Middle East & Africa | H32: iOS | I32: 2662259 | J32: 725513 | K32: =IF(I32=0,0,J32/I32) -> 0.27251781 | L32: 347882 | M32: 50059 | N32: 4207 | O32: 0 | P32: =M32+N32+O32 -> 54266 | Q32: =IF(I32=0,0,P32/I32) -> 0.020383441 | R32: 0.0475 | S32: 382515 | T32: 35052 | U32: 12212 | V32: 34187 | W32: =S32+T32+U32+V32 -> 463966 | X32: =IF(P32=0,0,S32/P32) -> 7.0488888 | Y32: =IF(J32=0,0,W32/J32) -> 0.6395006 | Z32: 83170 | AA32: =IF(L32=0,0,Z32/L32) -> 0.23907532 | AB32: 51780515 | AC32: 11.3 | AD32: 17.6 | AE32: 0.358 | AF32: 0.557 | AG32: 0.332 | AH32: 0.188 | AI32: 4.66
A33: 44958 | B33: =YEAR(A33) -> 2023 | C33: ="Q"&ROUNDUP(MONTH(A33)/3,0) -> Q1 | D33: =B33&"-"&C33 -> 2023-Q1 | E33: =MONTH(A33) -> 2 | F33: =TEXT(A33,"mmm") -> Feb | G33: Middle East & Africa | H33: Android | I33: 3338192 | J33: 868500 | K33: =IF(I33=0,0,J33/I33) -> 0.26017078 | L33: 430705 | M33: 25521 | N33: 2357 | O33: 0 | P33: =M33+N33+O33 -> 27878 | Q33: =IF(I33=0,0,P33/I33) -> 0.0083512273 | R33: 0.0455 | S33: 219874 | T33: 22596 | U33: 6453 | V33: 19687 | W33: =S33+T33+U33+V33 -> 268610 | X33: =IF(P33=0,0,S33/P33) -> 7.8870077 | Y33: =IF(J33=0,0,W33/J33) -> 0.30928037 | Z33: 53678 | AA33: =IF(L33=0,0,Z33/L33) -> 0.12462823 | AB33: 63509072 | AC33: 11.1 | AD33: 16.9 | AE33: 0.363 | AF33: 0.566 | AG33: 0.321 | AH33: 0.204 | AI33: 4.61
A34: 44958 | B34: =YEAR(A34) -> 2023 | C34: ="Q"&ROUNDUP(MONTH(A34)/3,0) -> Q1 | D34: =B34&"-"&C34 -> 2023-Q1 | E34: =MONTH(A34) -> 2 | F34: =TEXT(A34,"mmm") -> Feb | G34: Middle East & Africa | H34: Web | I34: 959891 | J34: 227811 | K34: =IF(I34=0,0,J34/I34) -> 0.23733007 | L34: 115145 | M34: 7541 | N34: 724 | O34: 0 | P34: =M34+N34+O34 -> 8265 | Q34: =IF(I34=0,0,P34/I34) -> 0.0086103526 | R34: 0.0511 | S34: 61813 | T34: 6071 | U34: 1839 | V34: 5038 | W34: =S34+T34+U34+V34 -> 74761 | X34: =IF(P34=0,0,S34/P34) -> 7.4788869 | Y34: =IF(J34=0,0,W34/J34) -> 0.32817116 | Z34: 12555 | AA34: =IF(L34=0,0,Z34/L34) -> 0.10903643 | AB34: 17276537 | AC34: 10.3 | AD34: 17.3 | AE34: 0.358 | AF34: 0.572 | AG34: 0.34 | AH34: 0.186
A35: 44958 | B35: =YEAR(A35) -> 2023 | C35: ="Q"&ROUNDUP(MONTH(A35)/3,0) -> Q1 | D35: =B35&"-"&C35 -> 2023-Q1 | E35: =MONTH(A35) -> 2 | F35: =TEXT(A35,"mmm") -> Feb | G35: South Asia | H35: iOS | I35: 4155485 | J35: 1161500 | K35: =IF(I35=0,0,J35/I35) -> 0.27951009 | L35: 560556 | M35: 95949 | N35: 8031 | O35: 0 | P35: =M35+N35+O35 -> 103980 | Q35: =IF(I35=0,0,P35/I35) -> 0.02502235 | R35: 0.0461 | S35: 785093 | T35: 80773 | U35: 24860 | V35: 69902 | W35: =S35+T35+U35+V35 -> 960628 | X35: =IF(P35=0,0,S35/P35) -> 7.5504232 | Y35: =IF(J35=0,0,W35/J35) -> 0.82705811 | Z35: 188668 | AA35: =IF(L35=0,0,Z35/L35) -> 0.33657297 | AB35: 80636355 | AC35: 11.5 | AD35: 17.4 | AE35: 0.352 | AF35: 0.57 | AG35: 0.326 | AH35: 0.186 | AI35: 4.63
A36: 44958 | B36: =YEAR(A36) -> 2023 | C36: ="Q"&ROUNDUP(MONTH(A36)/3,0) -> Q1 | D36: =B36&"-"&C36 -> 2023-Q1 | E36: =MONTH(A36) -> 2 | F36: =TEXT(A36,"mmm") -> Feb | G36: South Asia | H36: Android | I36: 5469816 | J36: 1369934 | K36: =IF(I36=0,0,J36/I36) -> 0.2504534 | L36: 617106 | M36: 55646 | N36: 5435 | O36: 0 | P36: =M36+N36+O36 -> 61081 | Q36: =IF(I36=0,0,P36/I36) -> 0.01116692 | R36: 0.0454 | S36: 425109 | T36: 44430 | U36: 13818 | V36: 34706 | W36: =S36+T36+U36+V36 -> 518063 | X36: =IF(P36=0,0,S36/P36) -> 6.9597584 | Y36: =IF(J36=0,0,W36/J36) -> 0.37816639 | Z36: 92683 | AA36: =IF(L36=0,0,Z36/L36) -> 0.15018976 | AB36: 95534293 | AC36: 11.2 | AD36: 17.8 | AE36: 0.374 | AF36: 0.549 | AG36: 0.316 | AH36: 0.196 | AI36: 4.61
A37: 44958 | B37: =YEAR(A37) -> 2023 | C37: ="Q"&ROUNDUP(MONTH(A37)/3,0) -> Q1 | D37: =B37&"-"&C37 -> 2023-Q1 | E37: =MONTH(A37) -> 2 | F37: =TEXT(A37,"mmm") -> Feb | G37: South Asia | H37: Web | I37: 1521900 | J37: 356730 | K37: =IF(I37=0,0,J37/I37) -> 0.23439779 | L37: 184206 | M37: 15283 | N37: 1432 | O37: 0 | P37: =M37+N37+O37 -> 16715 | Q37: =IF(I37=0,0,P37/I37) -> 0.010982982 | R37: 0.0488 | S37: 122653 | T37: 12349 | U37: 3852 | V37: 9802 | W37: =S37+T37+U37+V37 -> 148656 | X37: =IF(P37=0,0,S37/P37) -> 7.3379001 | Y37: =IF(J37=0,0,W37/J37) -> 0.41671853 | Z37: 26126 | AA37: =IF(L37=0,0,Z37/L37) -> 0.14183034 | AB37: 25646534 | AC37: 9.9 | AD37: 16.2 | AE37: 0.36 | AF37: 0.569 | AG37: 0.335 | AH37: 0.201
A38: 44986 | B38: =YEAR(A38) -> 2023 | C38: ="Q"&ROUNDUP(MONTH(A38)/3,0) -> Q1 | D38: =B38&"-"&C38 -> 2023-Q1 | E38: =MONTH(A38) -> 3 | F38: =TEXT(A38,"mmm") -> Mar | G38: North America | H38: iOS | I38: 6009649 | J38: 1774932 | K38: =IF(I38=0,0,J38/I38) -> 0.29534703 | L38: 952365 | M38: 1136978 | N38: 104408 | O38: 9608 | P38: =M38+N38+O38 -> 1250994 | Q38: =IF(I38=0,0,P38/I38) -> 0.20816424 | R38: 0.0436 | S38: 9904355 | T38: 1104501 | U38: 323231 | V38: 777297 | W38: =S38+T38+U38+V38 -> 12109384 | X38: =IF(P38=0,0,S38/P38) -> 7.9171883 | Y38: =IF(J38=0,0,W38/J38) -> 6.8224495 | Z38: 1984183 | AA38: =IF(L38=0,0,Z38/L38) -> 2.083427 | AB38: 125096392 | AC38: 11.7 | AD38: 17.2 | AE38: 0.361 | AF38: 0.556 | AG38: 0.328 | AH38: 0.195 | AI38: 4.63
A39: 44986 | B39: =YEAR(A39) -> 2023 | C39: ="Q"&ROUNDUP(MONTH(A39)/3,0) -> Q1 | D39: =B39&"-"&C39 -> 2023-Q1 | E39: =MONTH(A39) -> 3 | F39: =TEXT(A39,"mmm") -> Mar | G39: North America | H39: Android | I39: 7944145 | J39: 2171905 | K39: =IF(I39=0,0,J39/I39) -> 0.27339695 | L39: 1127036 | M39: 678808 | N39: 61146 | O39: 4287 | P39: =M39+N39+O39 -> 744241 | Q39: =IF(I39=0,0,P39/I39) -> 0.093684216 | R39: 0.0469 | S39: 5284267 | T39: 551525 | U39: 162726 | V39: 417087 | W39: =S39+T39+U39+V39 -> 6415605 | X39: =IF(P39=0,0,S39/P39) -> 7.1002095 | Y39: =IF(J39=0,0,W39/J39) -> 2.9539068 | Z39: 1218502 | AA39: =IF(L39=0,0,Z39/L39) -> 1.0811562 | AB39: 158937609 | AC39: 11.3 | AD39: 17.8 | AE39: 0.371 | AF39: 0.562 | AG39: 0.329 | AH39: 0.188 | AI39: 4.6
A40: 44986 | B40: =YEAR(A40) -> 2023 | C40: ="Q"&ROUNDUP(MONTH(A40)/3,0) -> Q1 | D40: =B40&"-"&C40 -> 2023-Q1 | E40: =MONTH(A40) -> 3 | F40: =TEXT(A40,"mmm") -> Mar | G40: North America | H40: Web | I40: 2360266 | J40: 601711 | K40: =IF(I40=0,0,J40/I40) -> 0.25493355 | L40: 293526 | M40: 187472 | N40: 16660 | O40: 787 | P40: =M40+N40+O40 -> 204919 | Q40: =IF(I40=0,0,P40/I40) -> 0.086820299 | R40: 0.052 | S40: 1519083 | T40: 148681 | U40: 45824 | V40: 118449 | W40: =S40+T40+U40+V40 -> 1832037 | X40: =IF(P40=0,0,S40/P40) -> 7.4130901 | Y40: =IF(J40=0,0,W40/J40) -> 3.0447125 | Z40: 340709 | AA40: =IF(L40=0,0,Z40/L40) -> 1.1607456 | AB40: 43809332 | AC40: 10.3 | AD40: 17.5 | AE40: 0.371 | AF40: 0.552 | AG40: 0.333 | AH40: 0.201
...

Sheet Fact_Language
A1: Date | B1: Year | C1: Quarter | D1: Language | E1: Language_Family | F1: Active_Learners | G1: New_Learners | H1: Lessons_Completed | I1: Avg_Daily_XP_per_Learner | J1: Course_Completion_Rate | K1: Avg_Streak_Days | L1: Share_of_Total_Learners
A2: 44927 | B2: =YEAR(A2) -> 2023 | C2: ="Q"&ROUNDUP(MONTH(A2)/3,0) -> Q1 | D2: English | E2: Germanic | F2: 24999265 | G2: 4855994 | H2: 348273398 | I2: 37.7 | J2: 0.104 | K2: 19.4 | L2: =IF(SUMIFS($F$2:$F$397,$A$2:$A$397,A2)=0,0,F2/SUMIFS($F$2:$F$397,$A$2:$A$397,A2)) -> 0.30444678
A3: 44927 | B3: =YEAR(A3) -> 2023 | C3: ="Q"&ROUNDUP(MONTH(A3)/3,0) -> Q1 | D3: Spanish | E3: Romance | F3: 14002081 | G3: 2476884 | H3: 194523308 | I3: 38.3 | J3: 0.129 | K3: 20 | L3: =IF(SUMIFS($F$2:$F$397,$A$2:$A$397,A3)=0,0,F3/SUMIFS($F$2:$F$397,$A$2:$A$397,A3)) -> 0.17052055
A4: 44927 | B4: =YEAR(A4) -> 2023 | C4: ="Q"&ROUNDUP(MONTH(A4)/3,0) -> Q1 | D4: French | E4: Romance | F4: 7614069 | G4: 1322542 | H4: 108008787 | I4: 38 | J4: 0.125 | K4: 17.7 | L4: =IF(SUMIFS($F$2:$F$397,$A$2:$A$397,A4)=0,0,F4/SUMIFS($F$2:$F$397,$A$2:$A$397,A4)) -> 0.092725879
A5: 44927 | B5: =YEAR(A5) -> 2023 | C5: ="Q"&ROUNDUP(MONTH(A5)/3,0) -> Q1 | D5: German | E5: Germanic | F5: 4871624 | G5: 864676 | H5: 67117354 | I5: 37.2 | J5: 0.114 | K5: 17.2 | L5: =IF(SUMIFS($F$2:$F$397,$A$2:$A$397,A5)=0,0,F5/SUMIFS($F$2:$F$397,$A$2:$A$397,A5)) -> 0.059327755
A6: 44927 | B6: =YEAR(A6) -> 2023 | C6: ="Q"&ROUNDUP(MONTH(A6)/3,0) -> Q1 | D6: Japanese | E6: East Asian | F6: 5698586 | G6: 1012918 | H6: 92388858 | I6: 43 | J6: 0.078 | K6: 24 | L6: =IF(SUMIFS($F$2:$F$397,$A$2:$A$397,A6)=0,0,F6/SUMIFS($F$2:$F$397,$A$2:$A$397,A6)) -> 0.069398688
A7: 44927 | B7: =YEAR(A7) -> 2023 | C7: ="Q"&ROUNDUP(MONTH(A7)/3,0) -> Q1 | D7: Korean | E7: East Asian | F7: 4266572 | G7: 722438 | H7: 65635808 | I7: 42.7 | J7: 0.094 | K7: 22.9 | L7: =IF(SUMIFS($F$2:$F$397,$A$2:$A$397,A7)=0,0,F7/SUMIFS($F$2:$F$397,$A$2:$A$397,A7)) -> 0.051959293
A8: 44927 | B8: =YEAR(A8) -> 2023 | C8: ="Q"&ROUNDUP(MONTH(A8)/3,0) -> Q1 | D8: Italian | E8: Romance | F8: 4379227 | G8: 803282 | H8: 58796910 | I8: 37.9 | J8: 0.117 | K8: 16.8 | L8: =IF(SUMIFS($F$2:$F$397,$A$2:$A$397,A8)=0,0,F8/SUMIFS($F$2:$F$397,$A$2:$A$397,A8)) -> 0.053331231
A9: 44927 | B9: =YEAR(A9) -> 2023 | C9: ="Q"&ROUNDUP(MONTH(A9)/3,0) -> Q1 | D9: Portuguese | E9: Romance | F9: 3155719 | G9: 502270 | H9: 44054990 | I9: 36.1 | J9: 0.122 | K9: 16.9 | L9: =IF(SUMIFS($F$2:$F$397,$A$2:$A$397,A9)=0,0,F9/SUMIFS($F$2:$F$397,$A$2:$A$397,A9)) -> 0.03843107
A10: 44927 | B10: =YEAR(A10) -> 2023 | C10: ="Q"&ROUNDUP(MONTH(A10)/3,0) -> Q1 | D10: Chinese (Mandarin) | E10: East Asian | F10: 3346604 | G10: 597410 | H10: 50073937 | I10: 41.2 | J10: 0.067 | K10: 21.8 | L10: =IF(SUMIFS($F$2:$F$397,$A$2:$A$397,A10)=0,0,F10/SUMIFS($F$2:$F$397,$A$2:$A$397,A10)) -> 0.040755711
A11: 44927 | B11: =YEAR(A11) -> 2023 | C11: ="Q"&ROUNDUP(MONTH(A11)/3,0) -> Q1 | D11: Hindi | E11: South Asian | F11: 2615084 | G11: 477706 | H11: 34747739 | I11: 38.2 | J11: 0.101 | K11: 15.7 | L11: =IF(SUMIFS($F$2:$F$397,$A$2:$A$397,A11)=0,0,F11/SUMIFS($F$2:$F$397,$A$2:$A$397,A11)) -> 0.031847093
A12: 44927 | B12: =YEAR(A12) -> 2023 | C12: ="Q"&ROUNDUP(MONTH(A12)/3,0) -> Q1 | D12: Other Languages | E12: Other | F12: 7164912 | G12: 1436051 | H12: 97810082 | I12: 35.3 | J12: 0.092 | K12: 14.6 | L12: =IF(SUMIFS($F$2:$F$397,$A$2:$A$397,A12)=0,0,F12/SUMIFS($F$2:$F$397,$A$2:$A$397,A12)) -> 0.087255942
A13: 44958 | B13: =YEAR(A13) -> 2023 | C13: ="Q"&ROUNDUP(MONTH(A13)/3,0) -> Q1 | D13: English | E13: Germanic | F13: 25580557 | G13: 4390131 | H13: 342762112 | I13: 37.9 | J13: 0.108 | K13: 19.3 | L13: =IF(SUMIFS($F$2:$F$397,$A$2:$A$397,A13)=0,0,F13/SUMIFS($F$2:$F$397,$A$2:$A$397,A13)) -> 0.30561303
... A397: 45992 | B397: =YEAR(A397) -> 2025 | C397: ="Q"&ROUNDUP(MONTH(A397)/3,0) -> Q4 | D397: Other Languages | E397: Other | F397: 15188051 | G397: 2232350 | H397: 237560596 | I397: 43.7 | J397: 0.101 | K397: 21.4 | L397: =IF(SUMIFS($F$2:$F$397,$A$2:$A$397,A397)=0,0,F397/SUMIFS($F$2:$F$397,$A$2:$A$397,A397)) -> 0.090344388

Sheet Quarterly_Summary
A1: Quarterly & Annual Summary (all values calculated from Fact_Monthly)
A2: Sample / illustrative data. Formulas use SUMIFS on Fact_Monthly, so this sheet updates automatically if you edit or extend the fact table.
A4: Year_Quarter | B4: Quarter_Start | C4: Total_Revenue_USD | D4: Subscription_Rev_USD | E4: Advertising_Rev_USD | F4: IAP_Rev_USD | G4: DET_Rev_USD | H4: Avg_DAU | I4: Avg_MAU | J4: DAU_MAU_Ratio | K4: Quarter_End_Paid_Subs | L4: Marketing_Spend_USD | M4: Subscription_Share | N4: Revenue_YoY | O4: DAU_YoY | P4: Paid_Subs_YoY | Q4: Revenue_QoQ
A5: 2023-Q1 | B5: 44927 | C5: =SUMIFS(Fact_Monthly!$W$2:$W$649,Fact_Monthly!$D$2:$D$649,$A5) -> 117360978 | D5: =SUMIFS(Fact_Monthly!$S$2:$S$649,Fact_Monthly!$D$2:$D$649,$A5) -> 96309897 | E5: =SUMIFS(Fact_Monthly!$T$2:$T$649,Fact_Monthly!$D$2:$D$649,$A5) -> 9936067 | F5: =SUMIFS(Fact_Monthly!$U$2:$U$649,Fact_Monthly!$D$2:$D$649,$A5) -> 3081458 | G5: =SUMIFS(Fact_Monthly!$V$2:$V$649,Fact_Monthly!$D$2:$D$649,$A5) -> 8033556 | H5: =SUMIFS(Fact_Monthly!$J$2:$J$649,Fact_Monthly!$D$2:$D$649,$A5)/3 -> 20497888 | I5: =SUMIFS(Fact_Monthly!$I$2:$I$649,Fact_Monthly!$D$2:$D$649,$A5)/3 -> 74807470 | J5: =IF(I5=0,0,H5/I5) -> 0.27400858 | K5: =SUMIFS(Fact_Monthly!$P$2:$P$649,Fact_Monthly!$A$2:$A$649,EDATE($B5,2)) -> 4600000 | L5: =SUMIFS(Fact_Monthly!$Z$2:$Z$649,Fact_Monthly!$D$2:$D$649,$A5) -> 22279392 | M5: =IF(C5=0,0,D5/C5) -> 0.82062964 | N5: n/a | O5: n/a | P5: n/a | Q5: n/a
A6: 2023-Q2 | B6: 45017 | C6: =SUMIFS(Fact_Monthly!$W$2:$W$649,Fact_Monthly!$D$2:$D$649,$A6) -> 126950441 | D6: =SUMIFS(Fact_Monthly!$S$2:$S$649,Fact_Monthly!$D$2:$D$649,$A6) -> 104575910 | E6: =SUMIFS(Fact_Monthly!$T$2:$T$649,Fact_Monthly!$D$2:$D$649,$A6) -> 10329970 | F6: =SUMIFS(Fact_Monthly!$U$2:$U$649,Fact_Monthly!$D$2:$D$649,$A6) -> 3566885 | G6: =SUMIFS(Fact_Monthly!$V$2:$V$649,Fact_Monthly!$D$2:$D$649,$A6) -> 8477676 | H6: =SUMIFS(Fact_Monthly!$J$2:$J$649,Fact_Monthly!$D$2:$D$649,$A6)/3 -> 22294833 | I6: =SUMIFS(Fact_Monthly!$I$2:$I$649,Fact_Monthly!$D$2:$D$649,$A6)/3 -> 78992248 | J6: =IF(I6=0,0,H6/I6) -> 0.28224078 | K6: =SUMIFS(Fact_Monthly!$P$2:$P$649,Fact_Monthly!$A$2:$A$649,EDATE($B6,2)) -> 5199999 | L6: =SUMIFS(Fact_Monthly!$Z$2:$Z$649,Fact_Monthly!$D$2:$D$649,$A6) -> 23550057 | M6: =IF(C6=0,0,D6/C6) -> 0.82375381 | N6: n/a | O6: n/a | P6: n/a | Q6: =IF(C5=0,0,C6/C5-1) -> 0.081709127
A7: 2023-Q3 | B7: 45108 | C7: =SUMIFS(Fact_Monthly!$W$2:$W$649,Fact_Monthly!$D$2:$D$649,$A7) -> 136411144 | D7: =SUMIFS(Fact_Monthly!$S$2:$S$649,Fact_Monthly!$D$2:$D$649,$A7) -> 112566703 | E7: =SUMIFS(Fact_Monthly!$T$2:$T$649,Fact_Monthly!$D$2:$D$649,$A7) -> 10847745 | F7: =SUMIFS(Fact_Monthly!$U$2:$U$649,Fact_Monthly!$D$2:$D$649,$A7) -> 4189718 | G7: =SUMIFS(Fact_Monthly!$V$2:$V$649,Fact_Monthly!$D$2:$D$649,$A7) -> 8806978 | H7: =SUMIFS(Fact_Monthly!$J$2:$J$649,Fact_Monthly!$D$2:$D$649,$A7)/3 -> 24165055 | I7: =SUMIFS(Fact_Monthly!$I$2:$I$649,Fact_Monthly!$D$2:$D$649,$A7)/3 -> 83173478 | J7: =IF(I7=0,0,H7/I7) -> 0.29053799 | K7: =SUMIFS(Fact_Monthly!$P$2:$P$649,Fact_Monthly!$A$2:$A$649,EDATE($B7,2)) -> 5800000 | L7: =SUMIFS(Fact_Monthly!$Z$2:$Z$649,Fact_Monthly!$D$2:$D$649,$A7) -> 24374118 | M7: =IF(C7=0,0,D7/C7) -> 0.82520166 | N7: n/a | O7: n/a | P7: n/a | Q7: =IF(C6=0,0,C7/C6-1) -> 0.074522805
A8: 2023-Q4 | B8: 45200 | C8: =SUMIFS(Fact_Monthly!$W$2:$W$649,Fact_Monthly!$D$2:$D$649,$A8) -> 151071959 | D8: =SUMIFS(Fact_Monthly!$S$2:$S$649,Fact_Monthly!$D$2:$D$649,$A8) -> 125620004 | E8: =SUMIFS(Fact_Monthly!$T$2:$T$649,Fact_Monthly!$D$2:$D$649,$A8) -> 11434308 | F8: =SUMIFS(Fact_Monthly!$U$2:$U$649,Fact_Monthly!$D$2:$D$649,$A8) -> 4816994 | G8: =SUMIFS(Fact_Monthly!$V$2:$V$649,Fact_Monthly!$D$2:$D$649,$A8) -> 9200653 | H8: =SUMIFS(Fact_Monthly!$J$2:$J$649,Fact_Monthly!$D$2:$D$649,$A8)/3 -> 27052664 | I8: =SUMIFS(Fact_Monthly!$I$2:$I$649,Fact_Monthly!$D$2:$D$649,$A8)/3 -> 90813685 | J8: =IF(I8=0,0,H8/I8) -> 0.29789193 | K8: =SUMIFS(Fact_Monthly!$P$2:$P$649,Fact_Monthly!$A$2:$A$649,EDATE($B8,2)) -> 6599999 | L8: =SUMIFS(Fact_Monthly!$Z$2:$Z$649,Fact_Monthly!$D$2:$D$649,$A8) -> 26557177 | M8: =IF(C8=0,0,D8/C8) -> 0.83152429 | N8: n/a | O8: n/a | P8: n/a | Q8: =IF(C7=0,0,C8/C7-1) -> 0.1074752
A9: 2024-Q1 | B9: 45292 | C9: =SUMIFS(Fact_Monthly!$W$2:$W$649,Fact_Monthly!$D$2:$D$649,$A9) -> 168258948 | D9: =SUMIFS(Fact_Monthly!$S$2:$S$649,Fact_Monthly!$D$2:$D$649,$A9) -> 140725265 | E9: =SUMIFS(Fact_Monthly!$T$2:$T$649,Fact_Monthly!$D$2:$D$649,$A9) -> 12196027 | F9: =SUMIFS(Fact_Monthly!$U$2:$U$649,Fact_Monthly!$D$2:$D$649,$A9) -> 5667424 | G9: =SUMIFS(Fact_Monthly!$V$2:$V$649,Fact_Monthly!$D$2:$D$649,$A9) -> 9670232 | H9: =SUMIFS(Fact_Monthly!$J$2:$J$649,Fact_Monthly!$D$2:$D$649,$A9)/3 -> 31504000 | I9: =SUMIFS(Fact_Monthly!$I$2:$I$649,Fact_Monthly!$D$2:$D$649,$A9)/3 -> 103215503 | J9: =IF(I9=0,0,H9/I9) -> 0.30522547 | K9: =SUMIFS(Fact_Monthly!$P$2:$P$649,Fact_Monthly!$A$2:$A$649,EDATE($B9,2)) -> 7400001 | L9: =SUMIFS(Fact_Monthly!$Z$2:$Z$649,Fact_Monthly!$D$2:$D$649,$A9) -> 29434127 | M9: =IF(C9=0,0,D9/C9) -> 0.83636126 | N9: =IF(C5=0,0,C9/C5-1) -> 0.43368734 | O9: =IF(H5=0,0,H9/H5-1) -> 0.53693882 | P9: =IF(K5=0,0,K9/K5-1) -> 0.60869587 | Q9: =IF(C8=0,0,C9/C8-1) -> 0.1137669
A10: 2024-Q2 | B10: 45383 | C10: =SUMIFS(Fact_Monthly!$W$2:$W$649,Fact_Monthly!$D$2:$D$649,$A10) -> 179511908 | D10: =SUMIFS(Fact_Monthly!$S$2:$S$649,Fact_Monthly!$D$2:$D$649,$A10) -> 150662502 | E10: =SUMIFS(Fact_Monthly!$T$2:$T$649,Fact_Monthly!$D$2:$D$649,$A10) -> 12353159 | F10: =SUMIFS(Fact_Monthly!$U$2:$U$649,Fact_Monthly!$D$2:$D$649,$A10) -> 6525998 | G10: =SUMIFS(Fact_Monthly!$V$2:$V$649,Fact_Monthly!$D$2:$D$649,$A10) -> 9970249 | H10: =SUMIFS(Fact_Monthly!$J$2:$J$649,Fact_Monthly!$D$2:$D$649,$A10)/3 -> 33799778 | I10: =SUMIFS(Fact_Monthly!$I$2:$I$649,Fact_Monthly!$D$2:$D$649,$A10)/3 -> 1.0818674e+08 | J10: =IF(I10=0,0,H10/I10) -> 0.31242071 | K10: =SUMIFS(Fact_Monthly!$P$2:$P$649,Fact_Monthly!$A$2:$A$649,EDATE($B10,2)) -> 8000001 | L10: =SUMIFS(Fact_Monthly!$Z$2:$Z$649,Fact_Monthly!$D$2:$D$649,$A10) -> 30079050 | M10: =IF(C10=0,0,D10/C10) -> 0.83928974 | N10: =IF(C6=0,0,C10/C6-1) -> 0.41403139 | O10: =IF(H6=0,0,H10/H6-1) -> 0.51603636 | P10: =IF(K6=0,0,K10/K6-1) -> 0.53846203 | Q10: =IF(C9=0,0,C10/C9-1) -> 0.066878821
A11: 2024-Q3 | B11: 45474 | C11: =SUMIFS(Fact_Monthly!$W$2:$W$649,Fact_Monthly!$D$2:$D$649,$A11) -> 191648808 | D11: =SUMIFS(Fact_Monthly!$S$2:$S$649,Fact_Monthly!$D$2:$D$649,$A11) -> 161243172 | E11: =SUMIFS(Fact_Monthly!$T$2:$T$649,Fact_Monthly!$D$2:$D$649,$A11) -> 12617867 | F11: =SUMIFS(Fact_Monthly!$U$2:$U$649,Fact_Monthly!$D$2:$D$649,$A11) -> 7507545 | G11: =SUMIFS(Fact_Monthly!$V$2:$V$649,Fact_Monthly!$D$2:$D$649,$A11) -> 10280224 | H11: =SUMIFS(Fact_Monthly!$J$2:$J$649,Fact_Monthly!$D$2:$D$649,$A11)/3 -> 36981223 | I11: =SUMIFS(Fact_Monthly!$I$2:$I$649,Fact_Monthly!$D$2:$D$649,$A11)/3 -> 1.1595619e+08 | J11: =IF(I11=0,0,H11/I11) -> 0.31892409 | K11: =SUMIFS(Fact_Monthly!$P$2:$P$649,Fact_Monthly!$A$2:$A$649,EDATE($B11,2)) -> 8599999 | L11: =SUMIFS(Fact_Monthly!$Z$2:$Z$649,Fact_Monthly!$D$2:$D$649,$A11) -> 33325037 | M11: =IF(C11=0,0,D11/C11) -> 0.84134712 | N11: =IF(C7=0,0,C11/C7-1) -> 0.40493513 | O11: =IF(H7=0,0,H11/H7-1) -> 0.53035954 | P11: =IF(K7=0,0,K11/K7-1) -> 0.48275845 | Q11: =IF(C10=0,0,C11/C10-1) -> 0.067610557
A12: 2024-Q4 | B12: 45566 | C12: =SUMIFS(Fact_Monthly!$W$2:$W$649,Fact_Monthly!$D$2:$D$649,$A12) -> 208538938 | D12: =SUMIFS(Fact_Monthly!$S$2:$S$649,Fact_Monthly!$D$2:$D$649,$A12) -> 176250966 | E12: =SUMIFS(Fact_Monthly!$T$2:$T$649,Fact_Monthly!$D$2:$D$649,$A12) -> 13095755 | F12: =SUMIFS(Fact_Monthly!$U$2:$U$649,Fact_Monthly!$D$2:$D$649,$A12) -> 8657854 | G12: =SUMIFS(Fact_Monthly!$V$2:$V$649,Fact_Monthly!$D$2:$D$649,$A12) -> 10534363 | H12: =SUMIFS(Fact_Monthly!$J$2:$J$649,Fact_Monthly!$D$2:$D$649,$A12)/3 -> 40740223 | I12: =SUMIFS(Fact_Monthly!$I$2:$I$649,Fact_Monthly!$D$2:$D$649,$A12)/3 -> 124925768 | J12: =IF(I12=0,0,H12/I12) -> 0.32611545 | K12: =SUMIFS(Fact_Monthly!$P$2:$P$649,Fact_Monthly!$A$2:$A$649,EDATE($B12,2)) -> 9500001 | L12: =SUMIFS(Fact_Monthly!$Z$2:$Z$649,Fact_Monthly!$D$2:$D$649,$A12) -> 34570393 | M12: =IF(C12=0,0,D12/C12) -> 0.84517054 | N12: =IF(C8=0,0,C12/C8-1) -> 0.38039474 | O12: =IF(H8=0,0,H12/H8-1) -> 0.50595973 | P12: =IF(K8=0,0,K12/K8-1) -> 0.43939431 | Q12: =IF(C11=0,0,C12/C11-1) -> 0.088130629
A13: 2025-Q1 | B13: 45658 | C13: =SUMIFS(Fact_Monthly!$W$2:$W$649,Fact_Monthly!$D$2:$D$649,$A13) -> 230270221 | D13: =SUMIFS(Fact_Monthly!$S$2:$S$649,Fact_Monthly!$D$2:$D$649,$A13) -> 195114155 | E13: =SUMIFS(Fact_Monthly!$T$2:$T$649,Fact_Monthly!$D$2:$D$649,$A13) -> 14093855 | F13: =SUMIFS(Fact_Monthly!$U$2:$U$649,Fact_Monthly!$D$2:$D$649,$A13) -> 9922225 | G13: =SUMIFS(Fact_Monthly!$V$2:$V$649,Fact_Monthly!$D$2:$D$649,$A13) -> 11139986 | H13: =SUMIFS(Fact_Monthly!$J$2:$J$649,Fact_Monthly!$D$2:$D$649,$A13)/3 -> 46496888 | I13: =SUMIFS(Fact_Monthly!$I$2:$I$649,Fact_Monthly!$D$2:$D$649,$A13)/3 -> 1.3898583e+08 | J13: =IF(I13=0,0,H13/I13) -> 0.3345441 | K13: =SUMIFS(Fact_Monthly!$P$2:$P$649,Fact_Monthly!$A$2:$A$649,EDATE($B13,2)) -> 10300000 | L13: =SUMIFS(Fact_Monthly!$Z$2:$Z$649,Fact_Monthly!$D$2:$D$649,$A13) -> 37766584 | M13: =IF(C13=0,0,D13/C13) -> 0.84732691 | N13: =IF(C9=0,0,C13/C9-1) -> 0.36854666 | O13: =IF(H9=0,0,H13/H9-1) -> 0.47590424 | P13: =IF(K9=0,0,K13/K9-1) -> 0.3918917 | Q13: =IF(C12=0,0,C13/C12-1) -> 0.10420732
A14: 2025-Q2 | B14: 45748 | C14: =SUMIFS(Fact_Monthly!$W$2:$W$649,Fact_Monthly!$D$2:$D$649,$A14) -> 254692620 | D14: =SUMIFS(Fact_Monthly!$S$2:$S$649,Fact_Monthly!$D$2:$D$649,$A14) -> 217230864 | E14: =SUMIFS(Fact_Monthly!$T$2:$T$649,Fact_Monthly!$D$2:$D$649,$A14) -> 14451128 | F14: =SUMIFS(Fact_Monthly!$U$2:$U$649,Fact_Monthly!$D$2:$D$649,$A14) -> 11457060 | G14: =SUMIFS(Fact_Monthly!$V$2:$V$649,Fact_Monthly!$D$2:$D$649,$A14) -> 11553568 | H14: =SUMIFS(Fact_Monthly!$J$2:$J$649,Fact_Monthly!$D$2:$D$649,$A14)/3 -> 47407834 | I14: =SUMIFS(Fact_Monthly!$I$2:$I$649,Fact_Monthly!$D$2:$D$649,$A14)/3 -> 139490656 | J14: =IF(I14=0,0,H14/I14) -> 0.33986387 | K14: =SUMIFS(Fact_Monthly!$P$2:$P$649,Fact_Monthly!$A$2:$A$649,EDATE($B14,2)) -> 10900000 | L14: =SUMIFS(Fact_Monthly!$Z$2:$Z$649,Fact_Monthly!$D$2:$D$649,$A14) -> 40288363 | M14: =IF(C14=0,0,D14/C14) -> 0.85291385 | N14: =IF(C10=0,0,C14/C10-1) -> 0.41880627 | O14: =IF(H10=0,0,H14/H10-1) -> 0.40260784 | P14: =IF(K10=0,0,K14/K10-1) -> 0.36249983 | Q14: =IF(C13=0,0,C14/C13-1) -> 0.10605974
A15: 2025-Q3 | B15: 45839 | C15: =SUMIFS(Fact_Monthly!$W$2:$W$649,Fact_Monthly!$D$2:$D$649,$A15) -> 275004253 | D15: =SUMIFS(Fact_Monthly!$S$2:$S$649,Fact_Monthly!$D$2:$D$649,$A15) -> 235256146 | E15: =SUMIFS(Fact_Monthly!$T$2:$T$649,Fact_Monthly!$D$2:$D$649,$A15) -> 14891354 | F15: =SUMIFS(Fact_Monthly!$U$2:$U$649,Fact_Monthly!$D$2:$D$649,$A15) -> 12940394 | G15: =SUMIFS(Fact_Monthly!$V$2:$V$649,Fact_Monthly!$D$2:$D$649,$A15) -> 11916359 | H15: =SUMIFS(Fact_Monthly!$J$2:$J$649,Fact_Monthly!$D$2:$D$649,$A15)/3 -> 50136055 | I15: =SUMIFS(Fact_Monthly!$I$2:$I$649,Fact_Monthly!$D$2:$D$649,$A15)/3 -> 1.4327329e+08 | J15: =IF(I15=0,0,H15/I15) -> 0.34993303 | K15: =SUMIFS(Fact_Monthly!$P$2:$P$649,Fact_Monthly!$A$2:$A$649,EDATE($B15,2)) -> 11500001 | L15: =SUMIFS(Fact_Monthly!$Z$2:$Z$649,Fact_Monthly!$D$2:$D$649,$A15) -> 42817982 | M15: =IF(C15=0,0,D15/C15) -> 0.85546366 | N15: =IF(C11=0,0,C15/C11-1) -> 0.4349385 | O15: =IF(H11=0,0,H15/H11-1) -> 0.35571652 | P15: =IF(K11=0,0,K15/K11-1) -> 0.33720957 | Q15: =IF(C14=0,0,C15/C14-1) -> 0.079749594
A16: 2025-Q4 | B16: 45931 | C16: =SUMIFS(Fact_Monthly!$W$2:$W$649,Fact_Monthly!$D$2:$D$649,$A16) -> 290229304 | D16: =SUMIFS(Fact_Monthly!$S$2:$S$649,Fact_Monthly!$D$2:$D$649,$A16) -> 249268066 | E16: =SUMIFS(Fact_Monthly!$T$2:$T$649,Fact_Monthly!$D$2:$D$649,$A16) -> 14768371 | F16: =SUMIFS(Fact_Monthly!$U$2:$U$649,Fact_Monthly!$D$2:$D$649,$A16) -> 14463011 | G16: =SUMIFS(Fact_Monthly!$V$2:$V$649,Fact_Monthly!$D$2:$D$649,$A16) -> 11729856 | H16: =SUMIFS(Fact_Monthly!$J$2:$J$649,Fact_Monthly!$D$2:$D$649,$A16)/3 -> 52910278 | I16: =SUMIFS(Fact_Monthly!$I$2:$I$649,Fact_Monthly!$D$2:$D$649,$A16)/3 -> 1.4915058e+08 | J16: =IF(I16=0,0,H16/I16) -> 0.35474403 | K16: =SUMIFS(Fact_Monthly!$P$2:$P$649,Fact_Monthly!$A$2:$A$649,EDATE($B16,2)) -> 12200000 | L16: =SUMIFS(Fact_Monthly!$Z$2:$Z$649,Fact_Monthly!$D$2:$D$649,$A16) -> 43375964 | M16: =IF(C16=0,0,D16/C16) -> 0.85886595 | N16: =IF(C12=0,0,C16/C12-1) -> 0.39172716 | O16: =IF(H12=0,0,H16/H12-1) -> 0.29872333 | P16: =IF(K12=0,0,K16/K12-1) -> 0.28421039 | Q16: =IF(C15=0,0,C16/C15-1) -> 0.055362966
A19: Annual Summary
A20: Year | B20: Total_Revenue_USD | C20: Revenue_YoY | D20: Avg_DAU | E20: Year_End_Paid_Subs | F20: Subscription_Share | G20: Marketing_Spend_USD
A21: 2023 | B21: =SUMIFS(Fact_Monthly!$W$2:$W$649,Fact_Monthly!$B$2:$B$649,$A21) -> 531794522 | C21: n/a | D21: =SUMIFS(Fact_Monthly!$J$2:$J$649,Fact_Monthly!$B$2:$B$649,$A21)/12 -> 23502610 | E21: =SUMIFS(Fact_Monthly!$P$2:$P$649,Fact_Monthly!$A$2:$A$649,DATE($A21,12,1)) -> 6599999 | F21: =IF(B21=0,0,SUMIFS(Fact_Monthly!$S$2:$S$649,Fact_Monthly!$B$2:$B$649,$A21)/B21) -> 0.82564317 | G21: =SUMIFS(Fact_Monthly!$Z$2:$Z$649,Fact_Monthly!$B$2:$B$649,$A21) -> 96760744
A22: 2024 | B22: =SUMIFS(Fact_Monthly!$W$2:$W$649,Fact_Monthly!$B$2:$B$649,$A22) -> 747958602 | C22: =IF(B21=0,0,B22/B21-1) -> 0.40648046 | D22: =SUMIFS(Fact_Monthly!$J$2:$J$649,Fact_Monthly!$B$2:$B$649,$A22)/12 -> 35756306 | E22: =SUMIFS(Fact_Monthly!$P$2:$P$649,Fact_Monthly!$A$2:$A$649,DATE($A22,12,1)) -> 9500001 | F22: =IF(B22=0,0,SUMIFS(Fact_Monthly!$S$2:$S$649,Fact_Monthly!$B$2:$B$649,$A22)/B22) -> 0.84079774 | G22: =SUMIFS(Fact_Monthly!$Z$2:$Z$649,Fact_Monthly!$B$2:$B$649,$A22) -> 127408607
A23: 2025 | B23: =SUMIFS(Fact_Monthly!$W$2:$W$649,Fact_Monthly!$B$2:$B$649,$A23) -> 1050196398 | C23: =IF(B22=0,0,B23/B22-1) -> 0.40408359 | D23: =SUMIFS(Fact_Monthly!$J$2:$J$649,Fact_Monthly!$B$2:$B$649,$A23)/12 -> 49237764 | E23: =SUMIFS(Fact_Monthly!$P$2:$P$649,Fact_Monthly!$A$2:$A$649,DATE($A23,12,1)) -> 12200000 | F23: =IF(B23=0,0,SUMIFS(Fact_Monthly!$S$2:$S$649,Fact_Monthly!$B$2:$B$649,$A23)/B23) -> 0.85400144 | G23: =SUMIFS(Fact_Monthly!$Z$2:$Z$649,Fact_Monthly!$B$2:$B$649,$A23) -> 164248893

Sheet Events
A1: Date | B1: Event | C1: Category | D1: Dashboard_Use
A2: 44986 | B2: Duolingo Max (GPT-4 powered tier) launched | C2: Product | D2: Annotation on Max_Subscribers / ARPPU trend
A3: 45689 | B3: 'Death of Duo' viral social campaign | C3: Marketing | D3: Annotation on New_Signups / DAU spike
A4: 45748 | B4: 148 new AI-generated language courses announced | C4: Content | D4: Annotation on Fact_Language learners (Hindi, Chinese, Korean, etc.)
A6: Dates are month-level; confirm exact dates against Duolingo announcements before publishing. Add your own rows below.
